<?xml version="1.0"?>
<robot name="Alfred" xmlns:xacro="http://www.ros.org/wiki/xacro">

  <material name="blue">
    <color rgba="0 0 0.8 1"/>
  </material>

  <material name="black">
    <color rgba="0 0 0 1"/>
  </material>

  <xacro:property name="bodyLength" value="0.15" />
  <xacro:property name="bodyHeight" value="0.10" />
  <xacro:property name="bodyDepth" value="0.07" />
  <xacro:property name="wheelRadius" value="0.035" />
  <xacro:property name="wheelWidth" value="0.03" />
  <xacro:property name="pi_2" value="1.57075" />

  <link name="dummy">
  </link>

  <link name="base_link">
    <visual>
      <geometry>
        <box size="${bodyLength} ${bodyDepth} ${bodyHeight}" />
      </geometry>
      <material name="black"/>
    </visual>
    <collision>
      <geometry>
        <box size="${bodyLength} ${bodyDepth} ${bodyHeight}" />
      </geometry>
    </collision>
    <inertial>
      <mass value="1"/>
      <inertia ixx="1.24e-3" ixy="0.0" ixz="0.0" iyy="2.28e-3" iyz="0.0" izz="2.71e-3"/>
    </inertial>
  </link>

  <joint name="dummy_joint" type="fixed">
    <parent link="dummy"/>
    <child link="base_link"/>
  </joint>

  <xacro:macro name="wheel" params="side">
    <link name="${side}_wheel">
      <visual>
        <geometry>
          <cylinder length="${wheelWidth}" radius="${wheelRadius}"/>
        </geometry>
        <origin rpy="0 ${pi_2} 0" xyz="0 0 0"/>
        <material name="blue"/>
      </visual>
      <collision>
        <geometry>
          <cylinder length="${wheelWidth}" radius="${wheelRadius}"/>
        </geometry>
        <origin rpy="0 ${pi_2} 0" xyz="0 0 0"/>
      </collision>
      <inertial>
        <mass value="0.03"/>
        <inertia ixx="1.14e-5" ixy="0.0" ixz="0.0" iyy="1.14e-5" iyz="0.0" izz="1.84e-5"/>
      </inertial>
    </link>

    <gazebo reference="${side}_wheel">
      <mu1 value="200.0"/>
      <mu2 value="100.0"/>
      <kp value="10000000.0" />
      <kd value="1.0" />
      <material>Gazebo/Grey</material>
    </gazebo>

  </xacro:macro>

  <xacro:wheel side="right">
  </xacro:wheel>

  <xacro:wheel side="left">
  </xacro:wheel>
 
  <joint name="base_to_right_wheel" type="continuous">
    <parent link="base_link"/>
    <child link="right_wheel"/>
    <origin xyz="0.09 0 -0.035"/>
    <axis xyz="1 0 0"/>
  </joint>

  <transmission name="right_wheel_rotation">
    <type>transmission_interface/SimpleTransmission</type>
    <actuator name="$right_wheel_motor">
      <mechanicalReduction>1</mechanicalReduction>
    </actuator>
    <joint name="base_to_right_wheel">
      <hardwareInterface>hardware_interface/VelocityJointInterface</hardwareInterface>
    </joint>
  </transmission>

  <joint name="base_to_left_wheel" type="continuous">
    <parent link="base_link"/>
    <child link="left_wheel"/>
    <origin xyz="-0.09 0 -0.035"/>
    <axis xyz="1 0 0"/>
  </joint>

  <transmission name="left_wheel_rotation">
    <type>transmission_interface/SimpleTransmission</type>
    <actuator name="$left_wheel_motor">
      <mechanicalReduction>1</mechanicalReduction>
    </actuator>
    <joint name="base_to_left_wheel">
      <hardwareInterface>hardware_interface/VelocityJointInterface</hardwareInterface>
    </joint>
  </transmission>

  <!-- Gazebo plugin for ROS Control -->
  <gazebo>
    <plugin name="gazebo_ros_control" filename="libgazebo_ros_control.so">
      <robotNamespace>/</robotNamespace>
    </plugin>
  </gazebo>

</robot>