<?xml version="1.0"?>
<robot name="Alfred">

  <material name="blue">
    <color rgba="0 0 0.8 1"/>
  </material>

  <material name="black">
    <color rgba="0 0 0 1"/>
  </material>

  <link name="base_link">
    <visual>
      <geometry>
        <box size="0.15 0.07 0.10" />
      </geometry>
      <origin rpy="0 0 0" xyz="0 0 0.08"/>
      <material name="black"/>
    </visual>
    <collision>
      <geometry>
        <box size="0.15 0.07 0.10" />
      </geometry>
    </collision>
    <inertial>
      <mass value="1"/>
      <inertia ixx="1.24e-3" ixy="0.0" ixz="0.0" iyy="2.28e-3" iyz="0.0" izz="2.71e-3"/>
    </inertial>
  </link>

  <link name="right_wheel">
    <visual>
      <geometry>
        <cylinder length="0.03" radius="0.035"/>
      </geometry>
      <origin rpy="0 1.57075 0" xyz="0.09 0 0"/>
      <material name="blue"/>
    </visual>
    <collision>
      <geometry>
        <cylinder length="0.03" radius="0.035"/>
      </geometry>
      <origin rpy="0 1.57075 0" xyz="0.09 0 0"/>
    </collision>
    <inertial>
      <mass value="0.03"/>
      <inertia ixx="1.14e-5" ixy="0.0" ixz="0.0" iyy="1.14e-5" iyz="0.0" izz="1.84e-5"/>
    </inertial>
  </link>

  <link name="left_wheel">
    <visual>
      <geometry>
        <cylinder length="0.03" radius="0.035"/>
      </geometry>
      <origin rpy="0 1.57075 0" xyz="-0.09 0 0"/>
      <material name="blue"/>
    </visual>
    <collision>
      <geometry>
        <cylinder length="0.03" radius="0.035"/>
      </geometry>
      <origin rpy="0 1.57075 0" xyz="-0.09 0 0"/>
    </collision>
    <inertial>
      <mass value="0.03"/>
      <inertia ixx="1.14e-5" ixy="0.0" ixz="0.0" iyy="1.14e-5" iyz="0.0" izz="1.84e-5"/>
    </inertial>
  </link>
  
  <joint name="base_to_right_wheel" type="revolute">
    <parent link="base_link"/>
    <child link="right_wheel"/>
    <origin xyz="0 0 0.035"/>
    <axis xyz="1 0 0"/>
  </joint>

  <joint name="base_to_left_wheel" type="revolute">
    <parent link="base_link"/>
    <child link="left_wheel"/>
    <origin xyz="0 0 0.035"/>
    <axis xyz="1 0 0"/>
  </joint>

</robot>