<?xml version="1.0" ?>
<!-- =================================================================================== -->
<!-- |    This document was autogenerated by xacro from alfred.xacro                   | -->
<!-- |    EDITING THIS FILE BY HAND IS NOT RECOMMENDED                                 | -->
<!-- =================================================================================== -->
<robot name="Alfred">
  <material name="blue">
    <color rgba="0 0 0.8 1"/>
  </material>
  <material name="black">
    <color rgba="0 0 0 1"/>
  </material>
  <!-- ################ -->
  <!-- Links definition -->
  <!-- ################ -->
  <link name="body">
    <visual>
      <geometry>
        <box size="0.15 0.09 0.11"/>
      </geometry>
      <material name="black"/>
    </visual>
    <collision>
      <geometry>
        <box size="0.15 0.09 0.11"/>
      </geometry>
    </collision>
    <inertial>
      <mass value="0.72"/>
      <inertia ixx="0.001212" ixy="0.0" ixz="0.0" iyy="0.001836" iyz="0.0" izz="0.0020759999999999997"/>
    </inertial>
    <sensor name="imu_sensor" type="imu">
      <always_on>1</always_on>
      <update_rate>1</update_rate>
      <visualize>true</visualize>
      <topic>imu</topic>
    </sensor>
  </link>
  <link name="right_wheel">
    <visual>
      <geometry>
        <cylinder length="0.035" radius="0.0375"/>
      </geometry>
      <origin rpy="0 1.5707963267948966 0" xyz="0 0 0"/>
      <material name="blue"/>
    </visual>
    <collision>
      <geometry>
        <cylinder length="0.035" radius="0.0375"/>
      </geometry>
      <origin rpy="0 1.5707963267948966 0" xyz="0 0 0"/>
    </collision>
    <inertial>
      <mass value="0.05"/>
      <inertia ixx="2.2682291666666666e-05" ixy="0.0" ixz="0.0" iyy="2.2682291666666666e-05" iyz="0.0" izz="3.515625e-05"/>
    </inertial>
  </link>
  <link name="left_wheel">
    <visual>
      <geometry>
        <cylinder length="0.035" radius="0.0375"/>
      </geometry>
      <origin rpy="0 1.5707963267948966 0" xyz="0 0 0"/>
      <material name="blue"/>
    </visual>
    <collision>
      <geometry>
        <cylinder length="0.035" radius="0.0375"/>
      </geometry>
      <origin rpy="0 1.5707963267948966 0" xyz="0 0 0"/>
    </collision>
    <inertial>
      <mass value="0.05"/>
      <inertia ixx="2.2682291666666666e-05" ixy="0.0" ixz="0.0" iyy="2.2682291666666666e-05" iyz="0.0" izz="3.515625e-05"/>
    </inertial>
  </link>
  <joint name="body_to_right_wheel" type="continuous">
    <parent link="body"/>
    <child link="right_wheel"/>
    <origin xyz="-0.09375 0 -0.04"/>
    <axis xyz="1 0 0"/>
  </joint>
  <joint name="body_to_left_wheel" type="continuous">
    <parent link="body"/>
    <child link="left_wheel"/>
    <origin xyz="0.09375 0 -0.04"/>
    <axis xyz="1 0 0"/>
  </joint>
  <transmission name="right_wheel_rotation">
    <type>transmission_interface/SimpleTransmission</type>
    <actuator name="right_wheel_motor">
      <mechanicalReduction>1</mechanicalReduction>
    </actuator>
    <joint name="body_to_right_wheel">
      <hardwareInterface>hardware_interface/VelocityJointInterface</hardwareInterface>
    </joint>
  </transmission>
  <transmission name="left_wheel_rotation">
    <type>transmission_interface/SimpleTransmission</type>
    <actuator name="left_wheel_motor">
      <mechanicalReduction>1</mechanicalReduction>
    </actuator>
    <joint name="body_to_left_wheel">
      <hardwareInterface>hardware_interface/VelocityJointInterface</hardwareInterface>
    </joint>
  </transmission>
  <!-- ################# -->
  <!-- Diff drive plugin -->
  <!-- ################# -->
  <plugin filename="gz-sim-diff-drive-system" name="gz::sim::systems::DiffDrive">
    <left_joint>left_wheel_joint</left_joint>
    <right_joint>right_wheel_joint</right_joint>
    <wheel_separation>1.2</wheel_separation>
    <wheel_radius>0.4</wheel_radius>
    <odom_publish_frequency>1</odom_publish_frequency>
    <topic>cmd_vel</topic>
  </plugin>
</robot>
