<?xml version="1.0"?>
<sdf version="1.8">
  <model name="Alfred">
    <!-- ################ -->
    <!-- Links definition -->
    <!-- ################ -->

    <!-- Body -->
    <link name="body">
      <visual name='visual'>
        <geometry>
          <box>
            <size>0.15 0.09 0.11</size>
          </box>
        </geometry>
        <material>
          <ambient>0.1 0.1 0.1 1</ambient>
          <diffuse>0.1 0.1 0.2 1</diffuse>
          <specular>0 0 0 0</specular>
        </material>
      </visual>
      <collision name='collision'>
        <geometry>
          <box>
            <size>0.15 0.09 0.11</size>
          </box>
        </geometry>
      </collision>
      <inertial>
        <mass>0.72</mass>
        <inertia>
          <ixx>0.001212</ixx>
          <ixy>0.0</ixy>
          <ixz>0.0</ixz>
          <iyy>0.001836</iyy>
          <iyz>0.0</iyz>
          <izz>0.0020759999999999997</izz>
        </inertia>
      </inertial>
      <!-- Imu sensor -->
      <sensor name="imu_sensor" type="imu">
        <pose relative_to='body'>0 0 0.05 0 0 0</pose>
        <always_on>1</always_on>
        <update_rate>100</update_rate>
        <visualize>true</visualize>
        <topic>imu</topic>
      </sensor>
      <!-- Proximity sensor -->
      <sensor name="ultrasonic" type="gpu_lidar">
        <pose relative_to='body'>0 0.045 0.055 0 0 3.1416</pose>
        <always_on>1</always_on>
        <update_rate>1</update_rate>
        <visualize>true</visualize>
        <topic>ultrasonic</topic>
        <lidar>
          <scan>
              <horizontal>
                <samples>1</samples>
                <resolution>1</resolution>
                <min_angle>-0.075</min_angle>
                <max_angle>0.075</max_angle>
              </horizontal>
              <vertical>
                <samples>1</samples>
                <resolution>1</resolution>
                <min_angle>-0.075</min_angle>
                <max_angle>0.075</max_angle>
              </vertical>
          </scan>
          <range>
            <min>0.02</min>
            <max>4</max>
            <resolution>0.005</resolution>
          </range>
          <noise>
            <type>gaussian</type>
            <mean>0.0</mean>
            <stddev>0.01</stddev>
          </noise>
        </lidar>
      </sensor>  
    </link>

    <!-- Right wheel -->
    <link name="right_wheel">
      <pose relative_to="body">-0.09375 0 -0.04 0 1.5707963267948966 0</pose>
      <visual name='visual'>
        <geometry>
          <cylinder>
            <length>0.035</length>
            <radius>0.0375</radius>
          </cylinder>
        </geometry>
        <material>
          <ambient>0.0 0.0 1.0 1</ambient>
          <diffuse>0.0 0.0 1.0 1</diffuse>
          <specular>0.0 0.0 1.0 1</specular>
        </material>
      </visual>
      <collision name='collision'>
        <geometry>
          <cylinder>
            <length>0.035</length>
            <radius>0.0375</radius>
          </cylinder>
        </geometry>
      </collision>
      <inertial>
        <mass>0.05</mass>
        <inertia>
          <ixx>2.2682291666666666e-05</ixx>
          <ixy>0.0</ixy>
          <ixz>0.0</ixz>
          <iyy>2.2682291666666666e-05</iyy>
          <iyz>0.0</iyz>
          <izz>3.515625e-05</izz>
        </inertia>
      </inertial>
    </link>

    <!-- Left wheel -->
    <link name="left_wheel">
      <pose relative_to="body">0.09375 0 -0.04 0 1.5707963267948966 0</pose>
      <visual name='visual'>
        <geometry>
          <cylinder>
            <length>0.035</length>
            <radius>0.0375</radius>
          </cylinder>
        </geometry>
        <material>
          <ambient>0.0 0.0 1.0 1</ambient>
          <diffuse>0.0 0.0 1.0 1</diffuse>
          <specular>0.0 0.0 1.0 1</specular>
        </material>
      </visual>
      <collision name='collision'>
        <geometry>
          <cylinder>
            <length>0.035</length>
            <radius>0.0375</radius>
          </cylinder>
        </geometry>
      </collision>
      <inertial>
        <mass>0.05</mass>
        <inertia>
          <ixx>2.2682291666666666e-05</ixx>
          <ixy>0.0</ixy>
          <ixz>0.0</ixz>
          <iyy>2.2682291666666666e-05</iyy>
          <iyz>0.0</iyz>
          <izz>3.515625e-05</izz>
        </inertia>
      </inertial>
    </link>

    <!-- ################ -->
    <!-- Joints definition -->
    <!-- ################ -->
    <joint name="body_to_right_wheel" type="revolute">
      <pose relative_to='right_wheel'/>
      <parent>body</parent>
      <child>right_wheel</child>
      <axis>
        <xyz expressed_in='body'>1 0 0</xyz>
        <limit>
          <lower>-1.79769e+308</lower>    <!--negative infinity-->
          <upper>1.79769e+308</upper>     <!--positive infinity-->
        </limit>
      </axis>
    </joint>
    <joint name="body_to_left_wheel" type="revolute">
      <pose relative_to='left_wheel'/>
      <parent>body</parent>
      <child>left_wheel</child>
      <axis>
        <xyz expressed_in='body'>1 0 0</xyz>
        <limit>
          <lower>-1.79769e+308</lower>    <!--negative infinity-->
          <upper>1.79769e+308</upper>     <!--positive infinity-->
        </limit>
      </axis>
    </joint>

    <!-- ################# -->
    <!-- Diff drive plugin -->
    <!-- ################# -->
    <plugin filename="gz-sim-diff-drive-system" name="gz::sim::systems::DiffDrive">
      <left_joint>body_to_left_wheel</left_joint>
      <right_joint>body_to_right_wheel</right_joint>
      <wheel_separation>0.185</wheel_separation>
      <wheel_radius>0.0375</wheel_radius>
      <odom_publish_frequency>100</odom_publish_frequency>
      <topic>cmd_vel</topic>
      <odom_topic>odometry</odom_topic>
    </plugin>
  </model>
</sdf>